<?xml version="1.0" ?>
<!-- Generated using onshape-to-robot -->
<!-- Onshape document_id: 8a7a4f7feddc94d149095e62 -->
<robot name="fastbot" xmlns:xacro="http://ros.org/wiki/xacro">
  <xacro:property name="PI" value="3.141592653589793" />

  <xacro:macro name="fastbot_body" params="robot_name">
    
    <!-- Dummy root link (no inertia) - fixes KDL warning -->
    <link name="${robot_name}_base_footprint">
    </link>

    <!-- Link base_link -->
    <link name="${robot_name}_base_link">
        <inertial>
        <origin xyz="-0.0554465 -0.0168128 0.0632551" rpy="0 0 0"/>
        <mass value="0.246919"/>
        <inertia ixx="0.000732026" ixy="8.62449e-08" ixz="-1.16621e-05" iyy="0.00094594" iyz="-1.42962e-08" izz="0.00081673"/>
        </inertial>
        <!-- Part base_link -->
        <visual>
        <origin xyz="0.015056 0.0431711 0.00134516" rpy="0 -0 -1.5708"/>
        <geometry>
            <mesh filename="package://fastbot_description/onshape/assets/base_link.stl"/>
        </geometry>
        <material name="base_link_material">
            <color rgba="0.262745 0.282353 0.301961 1"/>
        </material>
        </visual>
        <collision>
        <origin xyz="0.015056 0.0431711 0.00134516" rpy="0 -0 -1.5708"/>
        <geometry>
            <mesh filename="package://fastbot_description/onshape/assets/base_link.stl"/>
        </geometry>
        </collision>
    </link>

    <!-- Connect dummy to original base_link -->
    <joint name="${robot_name}_base_joint" type="fixed">
        <parent link="${robot_name}_base_footprint"/>
        <child link="${robot_name}_base_link"/>
        <origin xyz="0 0 0" rpy="0 0 0"/> 
    </joint>

    <!-- Link fastbot_motor -->
    <link name="${robot_name}_motor_1">
        <inertial>
        <origin xyz="0.0067446 0.0085 -0.00855065" rpy="0 0 0"/>
        <mass value="0.0339689"/>
        <inertia ixx="2.5517e-06" ixy="-3.26147e-15" ixz="-9.70451e-07" iyy="1.80062e-05" iyz="-1.94099e-15" izz="1.80884e-05"/>
        </inertial>
        <!-- Part fastbot_motor -->
        <visual>
        <origin xyz="0.0935 -0.00775 -0.036" rpy="-1.5708 -1.5708 0"/>
        <geometry>
            <mesh filename="package://fastbot_description/onshape/assets/fastbot_motor.stl"/>
        </geometry>
        <material name="fastbot_motor_material">
            <color rgba="0.129412 0.129412 0.129412 1"/>
        </material>
        </visual>
        <collision>
        <origin xyz="0.0935 -0.00775 -0.036" rpy="-1.5708 -1.5708 0"/>
        <geometry>
            <mesh filename="package://fastbot_description/onshape/assets/fastbot_motor.stl"/>
        </geometry>
        </collision>
    </link>

    <!-- Link wheel_right -->
    <link name="${robot_name}_wheel_right">
        <inertial>
        <origin xyz="0 0 0" rpy="0 0 0"/>
        <mass value="0.03"/>
        <inertia ixx="0.0001" ixy="0" ixz="0" iyy="0.0001" iyz="0" izz="0.0002"/>
        </inertial>
        <!-- Part tire_d65x25_v1 -->
        <visual>
        <origin xyz="0.1135 0.0162 0.103475" rpy="1.5708 1.5708 0"/>
        <geometry>
            <mesh filename="package://fastbot_description/onshape/assets/tire_d65x25_v1.stl"/>
        </geometry>
        <material name="tire_d65x25_v1_material">
            <color rgba="0.290196 0.290196 0.290196 1"/>
        </material>
        </visual>
        <collision>
        <origin xyz="0.1135 0.0162 0.103475" rpy="1.5708 1.5708 0"/>
        <geometry>
            <mesh filename="package://fastbot_description/onshape/assets/tire_d65x25_v1.stl"/>
        </geometry>
        </collision>
        <!-- Part wheel_d65x25_v1 -->
        <visual>
        <origin xyz="0.1135 0.0162 0.1039" rpy="1.5708 1.5708 0"/>
        <geometry>
            <mesh filename="package://fastbot_description/onshape/assets/wheel_d65x25_v1.stl"/>
        </geometry>
        <material name="wheel_d65x25_v1_material">
            <color rgba="1 0.933333 0.133333 1"/>
        </material>
        </visual>
        <collision>
        <origin xyz="0.1135 0.0162 0.1039" rpy="1.5708 1.5708 0"/>
        <geometry>
            <mesh filename="package://fastbot_description/onshape/assets/wheel_d65x25_v1.stl"/>
        </geometry>
        </collision>
    </link>

    <!-- Joint from fastbot_motor to wheel_right -->
    <joint name="${robot_name}_right_wheel" type="continuous">
        <origin xyz="-0.02 0.0085 -0.0191" rpy="0 0 0"/>
        <parent link="${robot_name}_motor_1"/>
        <child link="${robot_name}_wheel_right"/>
        <axis xyz="0 0 1"/>
        <limit effort="10" velocity="10"/>
    </joint>

    <!-- Joint from base_link to fastbot_motor -->
    <joint name="${robot_name}_right_motor" type="fixed">
        <origin xyz="-0.078444 -0.0408289 0.0260952" rpy="-1.5708 -2.73691e-47 2.498e-16"/>
        <parent link="${robot_name}_base_link"/>
        <child link="${robot_name}_motor_1"/>
        <axis xyz="0 0 1"/>
        <limit effort="10" velocity="10"/>
    </joint>
    
    <!-- Link fastbot_motor_2 -->
    <link name="${robot_name}_motor_2">
        <inertial>
        <origin xyz="0.0067446 -0.0085 -0.00855065" rpy="0 0 0"/>
        <mass value="0.0339689"/>
        <inertia ixx="2.5517e-06" ixy="-3.26147e-15" ixz="-9.70451e-07" iyy="1.80062e-05" iyz="-1.94099e-15" izz="1.80884e-05"/>
        </inertial>
        <!-- Part fastbot_motor_2 -->
        <visual>
        <origin xyz="0.0935 -0.02475 -0.036" rpy="-1.5708 -1.5708 0"/>
        <geometry>
            <mesh filename="package://fastbot_description/onshape/assets/fastbot_motor.stl"/>
        </geometry>
        <material name="fastbot_motor_2_material">
            <color rgba="0.129412 0.129412 0.129412 1"/>
        </material>
        </visual>
        <collision>
        <origin xyz="0.0935 -0.02475 -0.036" rpy="-1.5708 -1.5708 0"/>
        <geometry>
            <mesh filename="package://fastbot_description/onshape/assets/fastbot_motor.stl"/>
        </geometry>
        </collision>
    </link>

    <!-- Link wheel_left -->
    <link name="${robot_name}_wheel_left">
        <inertial>
        <origin xyz="0 0 0" rpy="0 0 0"/>
        <mass value="0.03"/>
        <inertia ixx="0.0001" ixy="0" ixz="0" iyy="0.0001" iyz="0" izz="0.0002"/>
        </inertial>
        <!-- Part wheel_d65x25_v1_2 -->
        <visual>
        <origin xyz="0.1135 0.0162 0.1039" rpy="1.5708 1.5708 0"/>
        <geometry>
            <mesh filename="package://fastbot_description/onshape/assets/wheel_d65x25_v1.stl"/>
        </geometry>
        <material name="wheel_d65x25_v1_2_material">
            <color rgba="1 0.933333 0.133333 1"/>
        </material>
        </visual>
        <collision>
        <origin xyz="0.1135 0.0162 0.1039" rpy="1.5708 1.5708 0"/>
        <geometry>
            <mesh filename="package://fastbot_description/onshape/assets/wheel_d65x25_v1.stl"/>
        </geometry>
        </collision>
        <!-- Part tire_d65x25_v1_2 -->
        <visual>
        <origin xyz="0.1135 0.0162 0.104325" rpy="1.5708 1.5708 0"/>
        <geometry>
            <mesh filename="package://fastbot_description/onshape/assets/tire_d65x25_v1.stl"/>
        </geometry>
        <material name="tire_d65x25_v1_2_material">
            <color rgba="0.290196 0.290196 0.290196 1"/>
        </material>
        </visual>
        <collision>
        <origin xyz="0.1135 0.0162 0.104325" rpy="1.5708 1.5708 0"/>
        <geometry>
            <mesh filename="package://fastbot_description/onshape/assets/tire_d65x25_v1.stl"/>
        </geometry>
        </collision>
    </link>

    <!-- Joint from fastbot_motor_2 to wheel_left -->
    <joint name="${robot_name}_left_wheel" type="continuous">
        <origin xyz="-0.02 -0.0085 -0.0191" rpy="0 0 0"/>
        <parent link="${robot_name}_motor_2"/>
        <child link="${robot_name}_wheel_left"/>
        <axis xyz="0 0 -1"/>
        <limit effort="10" velocity="10"/>
    </joint>

    <!-- Joint from base_link to fastbot_motor_2 -->
    <joint name="${robot_name}_left_motor" type="fixed">
        <origin xyz="-0.078444 0.00717107 0.0260952" rpy="1.5708 -2.96391e-30 2.56739e-16"/>
        <parent link="${robot_name}_base_link"/>
        <child link="${robot_name}_motor_2"/>
        <axis xyz="0 0 1"/>
        <limit effort="10" velocity="10"/>
    </joint>

    <!-- Link pololu_ball_caster -->
    <link name="${robot_name}_ball_caster">
        <inertial>
        <origin xyz="0 0 0" rpy="0 0 0"/>
        <mass value="1e-09"/>
        <inertia ixx="1e-09" ixy="0" ixz="0" iyy="1e-09" iyz="0" izz="1e-09"/>
        </inertial>
        <!-- Part pololu_ball_caster -->
        <visual>
        <origin xyz="0.006731 0 -0.0106945" rpy="-1.5708 -0 0"/>
        <geometry>
            <mesh filename="package://fastbot_description/onshape/assets/pololu_ball_caster.stl"/>
        </geometry>
        <material name="pololu_ball_caster_material">
            <color rgba="0.34902 0.376471 0.4 1"/>
        </material>
        </visual>
        <collision>
        <origin xyz="0.006731 0 -0.0106945" rpy="-1.5708 -0 0"/>
        <geometry>
            <mesh filename="package://fastbot_description/onshape/assets/pololu_ball_caster.stl"/>
        </geometry>
        </collision>
    </link>

    <!-- Joint from base_link to pololu_ball_caster -->
    <joint name="${robot_name}_caster" type="fixed">
        <origin xyz="5.59691e-05 -0.0241949 0.00334516" rpy="0 -0 1.5708"/>
        <parent link="${robot_name}_base_link"/>
        <child link="${robot_name}_ball_caster"/>
        <axis xyz="0 0 1"/>
        <limit effort="10" velocity="10"/>
    </joint>

    <!-- Link lslidar_n10 -->
    <link name="${robot_name}_lslidar_n10">
        <inertial>
            <origin xyz="0 0 0" rpy="0 0 0"/>
            <mass value="1e-09"/>
            <inertia ixx="1e-09" ixy="0" ixz="0" iyy="1e-09" iyz="0" izz="1e-09"/>
        </inertial>
        <!-- Part lslidar_n10 -->
        <visual>
            <origin xyz="0.074 0.06 -0.14585" rpy="0 0 -1.5708"/>
            <geometry>
                <mesh filename="package://fastbot_description/onshape/assets/lslidar_n10.stl"/>
            </geometry>
            <material name="lslidar_n10_material">
                <color rgba="0.0980392 0.0980392 0.0980392 1"/>
            </material>
        </visual>
        <collision>
            <origin xyz="0.074 0.06 -0.14585" rpy="0 0 -1.5708"/>
            <geometry>
                <mesh filename="package://fastbot_description/onshape/assets/lslidar_n10.stl"/>
            </geometry>
        </collision>
    </link>

    <!-- Joint from base_link to lslidar_n10 -->
    <joint name="${robot_name}_lidar" type="fixed">
        <origin xyz="-0.058944 -0.0168289 0.147435" rpy="0 0 0"/>
        <parent link="${robot_name}_base_link"/>
        <child link="${robot_name}_lslidar_n10"/>
    </joint>

    <!-- Link raspicam -->
    <link name="${robot_name}_camera">
        <inertial>
        <origin xyz="0 0 0" rpy="0 0 0"/>
        <mass value="1e-09"/>
        <inertia ixx="1e-09" ixy="0" ixz="0" iyy="1e-09" iyz="0" izz="1e-09"/>
        </inertial>
        <!-- Part raspicam -->
        <visual>
        <origin xyz="0 0 -0.0065" rpy="0 7.88861e-31 0"/>
        <geometry>
            <mesh filename="package://fastbot_description/onshape/assets/raspicam.stl"/>
        </geometry>
        <material name="raspicam_material">
            <color rgba="0.34902 0.376471 0.4 1"/>
        </material>
        </visual>
        <collision>
        <origin xyz="0 0 -0.0065" rpy="0 7.88861e-31 0"/>
        <geometry>
            <mesh filename="package://fastbot_description/onshape/assets/raspicam.stl"/>
        </geometry>
        </collision>
    </link>

    <!-- Joint from base_link to raspicam -->
    <joint name="${robot_name}_camera" type="fixed">
        <origin xyz="0.021056 -0.0168289 0.088598" rpy="1.5708 8.88178e-16 1.5708"/>
        <parent link="${robot_name}_base_link"/>
        <child link="${robot_name}_camera"/>
        <axis xyz="0 0 1"/>
        <limit effort="10" velocity="10"/>
    </joint>

   </xacro:macro>
   

</robot>
